Workbook

Sheet Sheet1
A1: ID | B1: 姓名 | C1: 性别 | D1: 世代 | E1: 分堂 | F1: 父亲ID | G1: 父亲姓名 | H1: 母亲ID | I1: 母亲姓名 | J1: 居住地 | K1: 墓葬地 | L1: 寿命 | M1: 出生日期 | N1: 出生朝代 | O1: 出生干支 | P1: 生肖 | Q1: 逝世日期 | R1: 逝世朝代 | S1: 逝世干支 | T1: 配偶ID | U1: 配偶姓名 | V1: 女婿ID | W1: 女婿姓名 | X1: 荣誉 | Y1: 功名 | Z1: 官职 | AA1: 个人详情
A2: M000001 | B2: 公瑾 | C2: 男 | D2: 1 | E2: 中和堂 | J2: 吉州 | K2: 东西塘岗背大埝 | Q2: 999.1.1 | R2: 北宋宋真宗咸平二年 | S2: 己亥年元月初一 | T2: M000001W01 | U2: 王氏 | X2: 基祖 | Z2: 怀远将军 | AA2: 公瑾 字友瑜，宋大宗太平兴国元年秋八月，擒宋德明等，以功为江南兵铃吉洲驻扎，咸平二年葬吉州西峯寺侧，后改葬东西塘岗背大埝，申山寅向，以弓剑实塚，故号弓剑塚。配王氏，子二：继隆、必渭。_x000D_ （古庐陵的东西塘，各个罗家家谱考证都在目前吉安市吉州区的长塘镇、曲濑镇一带。作为“临清罗氏”的一世祖开基地，这一带不仅是罗氏家族的祖源地，也承载着吉安典型的“庐陵文化”和“耕读文化”。阳先注）
A3: M000002 | B3: 继隆 | C3: 男 | D3: 2 | E3: 中和堂 | F3: M000001 | G3: 公瑾 | H3: =INDEX([1]妻子表!$A:$A,MATCH(F3,[1]妻子表!$B:$B,0)) -> M000001W01 | I3: =VLOOKUP(H3,[1]妻子表!$A:$D,4,0) -> 王氏 | J3: 陕西泾源 | Z3: 泾源节度使 | AA3: 继隆 字幼成，宋真宗天僖元年，以江东都统奉命收宗歌鬼章，留屯陕西拜泾源节度使，遂居于彼。
A4: M000003 | B4: 必渭 | C4: 男 | D4: 2 | E4: 中和堂 | F4: M000001 | G4: 公瑾 | H4: =INDEX([1]妻子表!$A:$A,MATCH(F4,[1]妻子表!$B:$B,0)) -> M000001W01 | I4: =VLOOKUP(H4,[1]妻子表!$A:$D,4,0) -> 王氏 | J4: 东西塘 | K4: 答田社山樟树下 | T4: M000003W01 | U4: 王氏 | AA4: 必渭 字季哲，天圣二年（公元1024年），因父墓改葬东西塘，遂家于此。配王氏。葬答田社山樟树下。子一：一襄。
A5: M000004 | B5: 一襄 | C5: 男 | D5: 3 | E5: 中和堂 | F5: M000003 | G5: 必渭 | H5: =INDEX([1]妻子表!$A:$A,MATCH(F5,[1]妻子表!$B:$B,0)) -> M000003W01 | I5: =VLOOKUP(H5,[1]妻子表!$A:$D,4,0) -> 王氏 | J5: 东西塘 | K5: 后园樟树下 | Q5: 1072.1.1 | R5: 北宋宋神宗熙宁五年 | S5: 壬子年元月初一 | T5: M000004W01,M000004W02 | U5: 王氏_x000D_ 邬氏 | AA5: 一襄 字群谟，殁于熙宁五年，配王氏。葬后园樟树下。复配邬氏，子三：重荣、重美、重昌。
A6: M000005 | B6: 重荣 | C6: 男 | D6: 4 | E6: 中和堂 | F6: M000004 | G6: 一襄 | H6: =INDEX([1]妻子表!$A:$A,MATCH(F6,[1]妻子表!$B:$B,0)) -> M000004W01 | I6: =VLOOKUP(H6,[1]妻子表!$A:$D,4,0) -> 王氏 | J6: 东西塘 | Q6: 1095.1.1 | R6: 北宋宋哲宗绍圣二年 | S6: 乙亥年元月初一 | T6: M000005W01,M000005W02,M000005W03 | U6: 王氏_x000D_ 陈氏_x000D_ 王氏 | AA6: 重荣 字纯仁，殁绍圣二年。配王氏，葬王家山，艮山坤向；继配陈氏，葬小溪边；配王氏，葬南家门。子二：宗彦、宗固。
A7: M000006 | B7: 重美 | C7: 男 | D7: 4 | E7: 中和堂 | F7: M000004 | G7: 一襄 | H7: =INDEX([1]妻子表!$A:$A,MATCH(F7,[1]妻子表!$B:$B,0)) -> M000004W01 | I7: =VLOOKUP(H7,[1]妻子表!$A:$D,4,0) -> 王氏 | J7: 东西塘
A8: M000007 | B8: 重昌 | C8: 男 | D8: 4 | E8: 中和堂 | F8: M000004 | G8: 一襄 | H8: =INDEX([1]妻子表!$A:$A,MATCH(F8,[1]妻子表!$B:$B,0)) -> M000004W01 | I8: =VLOOKUP(H8,[1]妻子表!$A:$D,4,0) -> 王氏 | J8: 东西塘 | AA8: 重昌 仍共居东西塘，其后俱未兴系。
A9: M000008 | B9: 宗彦 | C9: 男 | D9: 5 | E9: 中和堂 | F9: M000005 | G9: 重荣 | H9: =INDEX([1]妻子表!$A:$A,MATCH(F9,[1]妻子表!$B:$B,0)) -> M000005W01 | I9: =VLOOKUP(H9,[1]妻子表!$A:$D,4,0) -> 王氏 | J9: 东西塘 | Q9: 1122.1.1 | R9: 北宋宋徽宗宣和四年 | S9: 壬寅年元月初一 | T9: M000008W01,M000008W02,M000008W03,M000008W04,M000008W05 | U9: 王氏_x000D_ 刘氏_x000D_ 王氏_x000D_ 王氏_x000D_ 欧阳氏 | AA9: 字俊臣，殁宜和四年。元配王氏，葬河塘，艮山坤向；次配荷山刘氏，葬姑婆山东山申；三配王氏；四配王氏，葬东塘下；五配欧阳氏。子二：中成、中立。
A10: M000009 | B10: 宗固 | C10: 男 | D10: 5 | E10: 中和堂 | F10: M000005 | G10: 重荣 | H10: =INDEX([1]妻子表!$A:$A,MATCH(F10,[1]妻子表!$B:$B,0)) -> M000005W01 | I10: =VLOOKUP(H10,[1]妻子表!$A:$D,4,0) -> 王氏 | J10: 东西塘 | AA10: 宗固 仍居东西塘，其后未兴系。
A11: M000010 | B11: 中成 | C11: 男 | D11: 6 | E11: 中和堂 | F11: M000008 | G11: 宗彦 | H11: =INDEX([1]妻子表!$A:$A,MATCH(F11,[1]妻子表!$B:$B,0)) -> M000008W01 | I11: =VLOOKUP(H11,[1]妻子表!$A:$D,4,0) -> 王氏 | J11: 东西塘 | K11: 田南 | T11: M000010W01 | U11: 彭氏 | AA11: 字子美，殁葬田南，配丰塘彭氏。子三：惠迪，惠怀、惠民。
A12: M000011 | B12: 中立 | C12: 男 | D12: 6 | E12: 中和堂 | F12: M000008 | G12: 宗彦 | H12: =INDEX([1]妻子表!$A:$A,MATCH(F12,[1]妻子表!$B:$B,0)) -> M000008W01 | I12: =VLOOKUP(H12,[1]妻子表!$A:$D,4,0) -> 王氏 | J12: 东西塘 | AA12: 仍 居东西塘，其后未兴系。
A13: M000012 | B13: 惠迪 | C13: 男 | D13: 7 | E13: 中和堂 | F13: M000010 | G13: 中成 | H13: =INDEX([1]妻子表!$A:$A,MATCH(F13,[1]妻子表!$B:$B,0)) -> M000010W01 | I13: =VLOOKUP(H13,[1]妻子表!$A:$D,4,0) -> 彭氏 | J13: 东西塘 | K13: 沙江 | L13: 82 | M13: 1104.1.1 | N13: 北宋宋徽宗崇宁三年 | O13: 甲申年元月初一 | P13: 猴 | Q13: 1186.5.29 | R13: 南宋宋孝宗淳熙十三年 | S13: 丙午年五月廿九 | T13: M000012W01,M000012W02 | U13: 王氏_x000D_ 李氏 | Z13: 迪功郎 | AA13: 字长吉，甲辰庆典迪功郎致仕，寿八十，殁丙午年五月二十九日。配王氏，合葬沙江。续配彭田李氏，殁葬池墓。子二：世显、世修。（阳先注：南宋大文豪杨万里是吉水人，与惠迪公是同时代，杨的《長慶寺十八羅漢記 / 誠齋集》中就记载了惠迪公的事迹，而长庆寺旧址区域就在吉州区长塘镇附近，也是我罗氏家族集聚地东西塘的核心区域。在各种罗家家谱记载中，常录有在长庆寺相关的活动。迪功郎是一个虚衔，但也有资格做到主簿、尉、司户参军等类似的基层官职）
A14: M000013 | B14: 惠怀 | C14: 男 | D14: 7 | E14: 中和堂 | F14: M000010 | G14: 中成 | H14: =INDEX([1]妻子表!$A:$A,MATCH(F14,[1]妻子表!$B:$B,0)) -> M000010W01 | I14: =VLOOKUP(H14,[1]妻子表!$A:$D,4,0) -> 彭氏 | J14: 东西塘
A15: M000014 | B15: 惠民 | C15: 男 | D15: 7 | E15: 中和堂 | F15: M000010 | G15: 中成 | H15: =INDEX([1]妻子表!$A:$A,MATCH(F15,[1]妻子表!$B:$B,0)) -> M000010W01 | I15: =VLOOKUP(H15,[1]妻子表!$A:$D,4,0) -> 彭氏 | J15: 东西塘 | AA15: 惠民 仍共居东西塘，其后俱未兴系。
A16: M000015 | B16: 世显 | C16: 男 | D16: 8 | E16: 中和堂 | F16: M000012 | G16: 惠迪 | H16: =INDEX([1]妻子表!$A:$A,MATCH(F16,[1]妻子表!$B:$B,0)) -> M000012W01 | I16: =VLOOKUP(H16,[1]妻子表!$A:$D,4,0) -> 王氏 | J16: 东西塘 | K16: 大田 | T16: M000015W01 | U16: 王氏 | AA16: 世显 字周卿，殁葬大田，乙山辛向。配什乡王氏，子一：逢辰。
A17: M000016 | B17: 世修 | C17: 男 | D17: 8 | E17: 中和堂 | F17: M000012 | G17: 惠迪 | H17: =INDEX([1]妻子表!$A:$A,MATCH(F17,[1]妻子表!$B:$B,0)) -> M000012W01 | I17: =VLOOKUP(H17,[1]妻子表!$A:$D,4,0) -> 王氏 | J17: 东西塘 | AA17: 世修 仍君东西塘，其后未兴系。
A18: M000017 | B18: 逢辰 | C18: 男 | D18: 9 | E18: 中和堂 | F18: M000015 | G18: 世显 | H18: =INDEX([1]妻子表!$A:$A,MATCH(F18,[1]妻子表!$B:$B,0)) -> M000015W01 | I18: =VLOOKUP(H18,[1]妻子表!$A:$D,4,0) -> 王氏 | J18: 东西塘 | K18: 西村才坑 | Q18: 1240.8.25 | R18: 南宋宋理宗嘉熙四年 | S18: 庚子年八月廿五 | T18: M000017W01 | U18: 李氏 | AA18: 逢辰 字梦良，殁庚子八月二十五日，葬西村才坑。配彭田李氏，子一：宏仁。
A19: M000018 | B19: 宏仁 | C19: 男 | D19: 10 | E19: 中和堂 | F19: M000017 | G19: 逢辰 | H19: =INDEX([1]妻子表!$A:$A,MATCH(F19,[1]妻子表!$B:$B,0)) -> M000017W01 | I19: =VLOOKUP(H19,[1]妻子表!$A:$D,4,0) -> 李氏 | J19: 东西塘 | T19: M000018W01 | U19: 李氏 | AA19: 宏仁 字正己，配李氏。子四：浩然、涣然、渊然、沛然。
A20: M000019 | B20: 浩然 | C20: 男 | D20: 11 | E20: 中和堂 | F20: M000018 | G20: 宏仁 | H20: =INDEX([1]妻子表!$A:$A,MATCH(F20,[1]妻子表!$B:$B,0)) -> M000018W01 | I20: =VLOOKUP(H20,[1]妻子表!$A:$D,4,0) -> 李氏 | J20: 东西塘
A21: M000020 | B21: 涣然 | C21: 男 | D21: 11 | E21: 中和堂 | F21: M000018 | G21: 宏仁 | H21: =INDEX([1]妻子表!$A:$A,MATCH(F21,[1]妻子表!$B:$B,0)) -> M000018W01 | I21: =VLOOKUP(H21,[1]妻子表!$A:$D,4,0) -> 李氏 | J21: 安福县前 | T21: M000020W01 | U21: 彭氏 | X21: 安福基祖 | AA21: 涣然 由庐陵儒行乡东西塘徙居安福县前，是为安福基祖。配彭氏，子二：七郎、廷珍。（阳先注：庐陵儒行乡东西塘，儒行乡就是目前的吉州区桐坪镇、长塘镇、固江镇一带，目前桐坪镇山头村委会楼下村皆为罗姓，谱名《万卷楼》，我父亲与该村罗建永有联系。该村最接近历史上的东西塘旧址。安福县城铁冶巷）
A22: M000021 | B22: 渊然 | C22: 男 | D22: 11 | E22: 中和堂 | F22: M000018 | G22: 宏仁 | H22: =INDEX([1]妻子表!$A:$A,MATCH(F22,[1]妻子表!$B:$B,0)) -> M000018W01 | I22: =VLOOKUP(H22,[1]妻子表!$A:$D,4,0) -> 李氏 | J22: 安福
A23: M000022 | B23: 沛然 | C23: 男 | D23: 11 | E23: 中和堂 | F23: M000018 | G23: 宏仁 | H23: =INDEX([1]妻子表!$A:$A,MATCH(F23,[1]妻子表!$B:$B,0)) -> M000018W01 | I23: =VLOOKUP(H23,[1]妻子表!$A:$D,4,0) -> 李氏 | J23: 安福
A24: M000023 | B24: 七郎 | C24: 男 | D24: 12 | E24: 中和堂 | F24: M000020 | G24: 涣然 | H24: =INDEX([1]妻子表!$A:$A,MATCH(F24,[1]妻子表!$B:$B,0)) -> M000020W01 | I24: =VLOOKUP(H24,[1]妻子表!$A:$D,4,0) -> 彭氏 | J24: 安福
A25: M000024 | B25: 廷珍 | C25: 男 | D25: 12 | E25: 中和堂 | F25: M000020 | G25: 涣然 | H25: =INDEX([1]妻子表!$A:$A,MATCH(F25,[1]妻子表!$B:$B,0)) -> M000020W01 | I25: =VLOOKUP(H25,[1]妻子表!$A:$D,4,0) -> 彭氏 | J25: 德州 | L25: 53 | M25: 1241.1.1 | N25: 南宋宋理宗淳祐元年 | O25: 辛丑年元月初一 | P25: 牛 | Q25: 1294.1.1 | R25: 元朝至元三十一年 | S25: 甲午年元月初一 | T25: M000024W01 | U25: 刘氏 | AA25: 生宋淳佑辛丑年，赘社州生宋淳佑辛丑年，赘社州刘氏，随外氏仕德州，殁元至元甲午年。子一：定。，随外氏仕德州，殁元至元甲午年。子一：定。
A26: M000025 | B26: 定 | C26: 男 | D26: 13 | E26: 中和堂 | F26: M000024 | G26: 廷珍 | H26: =INDEX([1]妻子表!$A:$A,MATCH(F26,[1]妻子表!$B:$B,0)) -> M000024W01 | I26: =VLOOKUP(H26,[1]妻子表!$A:$D,4,0) -> 周氏 | J26: 安福 | K26: 鱼形 | L26: 66 | M26: 1290.1.1 | N26: 元朝至元二十七年 | O26: 庚寅年元月初一 | P26: 虎 | Q26: 1356.1.1 | R26: 元朝至正十六年 | S26: 丙申年元月初一 | T26: M000025W01 | U26: 周氏 | AA26: 生元至元庚寅年，殁至正丙申年，葬义历马凉丘鱼形壬子山丙午向。配泥田周氏，同葬鱼形。子一：原。
A27: M000026 | B27: 原 | C27: 男 | D27: 14 | E27: 中和堂 | F27: M000025 | G27: 定 | H27: =INDEX([1]妻子表!$A:$A,MATCH(F27,[1]妻子表!$B:$B,0)) -> M000025W01 | I27: =VLOOKUP(H27,[1]妻子表!$A:$D,4,0) -> 周氏 | J27: 鹧湖 | K27: 荷叶盏金龟形 | L27: 42 | M27: 1334.1.1 | N27: 元朝元统二年 | O27: 甲戌年元月初一 | P27: 狗 | Q27: 1376.1.1 | R27: 明朝洪武九年 | S27: 丙辰年元月初一 | T27: M000026W01 | U27: 彭氏 | X27: 鹧湖基祖 | AA27: 生元至统甲戌年，赘义历鹧湖彭氏，遂家于此，是为鹧湖基祖，殁明洪武丙辰（1376年），葬荷叶盏金龟形亥山，巽巳向。配彭氏，生元至元戊寅年，殁明永乐丙戌（1406年），附葬鹧湖金龟形右。子四：佰玉、孟邦、仲邦、季邦。(鹧湖：现竹江乡圳上村）
A28: M000027 | B28: 佰玉 | C28: 男 | D28: 15 | E28: 中和堂 | F28: M000026 | G28: 原 | H28: =INDEX([1]妻子表!$A:$A,MATCH(F28,[1]妻子表!$B:$B,0)) -> M000026W01 | I28: =VLOOKUP(H28,[1]妻子表!$A:$D,4,0) -> 彭氏 | J28: 鹧湖
A29: M000028 | B29: 孟邦 | C29: 男 | D29: 15 | E29: 中和堂 | F29: M000026 | G29: 原 | H29: =INDEX([1]妻子表!$A:$A,MATCH(F29,[1]妻子表!$B:$B,0)) -> M000026W01 | I29: =VLOOKUP(H29,[1]妻子表!$A:$D,4,0) -> 彭氏 | J29: 鹧湖
A30: M000029 | B30: 仲邦 | C30: 男 | D30: 15 | E30: 中和堂 | F30: M000026 | G30: 原 | H30: =INDEX([1]妻子表!$A:$A,MATCH(F30,[1]妻子表!$B:$B,0)) -> M000026W01 | I30: =VLOOKUP(H30,[1]妻子表!$A:$D,4,0) -> 彭氏 | J30: 鹧湖 | T30: M000029W01 | U30: 朱氏 | AA30: 字继昌，配朱氏。子一：筮元。
A31: M000030 | B31: 季邦 | C31: 男 | D31: 15 | E31: 中和堂 | F31: M000026 | G31: 原 | H31: =INDEX([1]妻子表!$A:$A,MATCH(F31,[1]妻子表!$B:$B,0)) -> M000026W01 | I31: =VLOOKUP(H31,[1]妻子表!$A:$D,4,0) -> 彭氏 | J31: 鹧湖 | K31: 蒙岗山秀峰庵后狪形铃上穴 | L31: 86 | M31: 1375.10.1 | N31: 明朝洪武八年 | O31: 乙卯年十月初一 | P31: 兔 | Q31: 1461.1.1 | R31: 明朝天顺五年 | S31: 辛巳年元月初一 | T31: M000030W01,M000030W02 | U31: 戴氏_x000D_ 熊氏 | AA31: 季邦 字继仁，生明洪武乙卯（1375年）十月初一日，殁天顺辛巳（1461年），葬蒙岗山秀峰庵后狪形铃上穴卯乙山，西辛向。配书岗戴氏，生洪武戊午（1378年），殁永乐戊子（1408年），葬二都下田宝成寺后龟形癸丑山，丁未向。继配熊氏，无子，殁天顺戊寅（1458年），附葬戴氏之右。子二：明、斐佩。
A32: M000031 | B32: 筮元 | C32: 男 | D32: 16 | E32: 中和堂 | F32: M000029 | G32: 仲邦 | H32: =INDEX([1]妻子表!$A:$A,MATCH(F32,[1]妻子表!$B:$B,0)) -> M000029W01 | I32: =VLOOKUP(H32,[1]妻子表!$A:$D,4,0) -> 朱氏 | J32: 高州 | K32: 凤形 | L32: 67 | M32: 1414.4.3 | N32: 明朝永乐十二年 | O32: 甲午年四月初三 | P32: 马 | Q32: 1481.10.14 | R32: 明朝成化十七年 | S32: 辛丑年十月十四 | T32: M000031W01 | U32: 陈氏 | X32: _x000D_ 高洲基祖 | Y32: 邑庠生 | AA32: 字料随、治易经、邑庠生。由东乡鹧湖，徙居南乡三十六都高州，是为高洲基祖。生永乐十二年甲午（1414年）四月初三日，殁成化十七年辛丑（1481年）十月十四日，葬本里板背沙巢凤形，癸山丁向。配枣树下陈氏，生明永乐丙申（1416年）年七月二十三日，殁成化八年壬辰（1472年）十一月初五日，同葬凤形。子二：斗珠、正珠。（阳先注：邑庠生就是县学生员（秀才），暂时没有找到筮元公的史料。）
A33: M000032 | B33: 明 | C33: 男 | D33: 16 | E33: 中和堂 | F33: M000030 | G33: 季邦 | H33: =INDEX([1]妻子表!$A:$A,MATCH(F33,[1]妻子表!$B:$B,0)) -> M000030W01 | I33: =VLOOKUP(H33,[1]妻子表!$A:$D,4,0) -> 戴氏 | J33: 南京 | K33: 龟形 | L33: 84 | M33: 1401.11.24 | N33: 明朝建文三年 | O33: 辛巳年十一月廿四 | P33: 蛇 | Q33: 1485.8.12 | R33: 明朝成化二十一年 | S33: 乙巳年八月十二 | T33: M000032W01 | U33: 王氏 | Z33: 南京山东道监察御史(赠) | AA33: 字处约、号拙轩、以子贵，勅赠南京山东道监察御史，生明洪武辛巳（1401年）十一月二十四日，殁成化乙巳（1485年）八月十二日，葬北乡二都下田宝成寺后龟形，丑艮山未坤向。配冷溪王氏，以子贵，勅赠孺人，生永乐丙戌（1406年）十月十二日，殁宏治乙卯（1495年）五月初二日，同葬龟形。子一：善。（阳先注：勅赠南京山东道监察御史，这是一个官不大但权大的官职，勅赠表示儿子善公立了功劳，追封先父的官职）
A34: M000033 | B34: 斐佩 | C34: 男 | D34: 16 | E34: 中和堂 | F34: M000030 | G34: 季邦 | H34: =INDEX([1]妻子表!$A:$A,MATCH(F34,[1]妻子表!$B:$B,0)) -> M000030W01 | I34: =VLOOKUP(H34,[1]妻子表!$A:$D,4,0) -> 戴氏 | J34: 鹧湖 | AA34: 子三，居鹧湖，世系未详。
A35: M000034 | B35: 斗珠 | C35: 男 | D35: 17 | E35: 中和堂 | F35: M000031 | G35: 筮元 | H35: =INDEX([1]妻子表!$A:$A,MATCH(F35,[1]妻子表!$B:$B,0)) -> M000031W01 | I35: =VLOOKUP(H35,[1]妻子表!$A:$D,4,0) -> 陈氏 | J35: 高州 | K35: 板背沙巢凤形 | M35: 1442.2.1 | N35: 明朝正统七年 | O35: 壬戌年二月初一 | P35: 狗 | T35: M000034W01 | U35: 曾氏 | AA35: 字显堂，生明正统七年壬戌（1442年）二月初一日，殁葬板背沙巢凤形。配曾氏，生明正统丙寅（1446年）三月初六日，殁葬凤形。子三：英、华、芬。
A36: M000035 | B36: 正珠 | C36: 男 | D36: 17 | E36: 中和堂 | F36: M000031 | G36: 筮元 | H36: =INDEX([1]妻子表!$A:$A,MATCH(F36,[1]妻子表!$B:$B,0)) -> M000031W01 | I36: =VLOOKUP(H36,[1]妻子表!$A:$D,4,0) -> 陈氏 | J36: 高州 | K36: 本里板背沙巢凤形 | M36: 1445.2.3 | N36: 明朝正统十年 | O36: 乙丑年二月初三 | P36: 牛 | T36: M000035W01 | U36: 刘氏 | AA36: 字焕堂，生正统乙丑（1445年）二月初三日，殁。配刘氏，同葬本里板背沙巢凤形，癸山丁向。子一、芃。
A37: M000036 | B37: 善 | C37: 男 | D37: 17 | E37: 中和堂 | F37: M000032 | G37: 明 | H37: =INDEX([1]妻子表!$A:$A,MATCH(F37,[1]妻子表!$B:$B,0)) -> M000032W01 | I37: =VLOOKUP(H37,[1]妻子表!$A:$D,4,0) -> 王氏 | J37: 北乡 | K37: 义历鱼形 | L37: 92 | M37: 1449.8.5 | N37: 明朝正统十四年 | O37: 己巳年八月初五 | P37: 蛇 | Q37: 1541.10.8 | R37: 明朝嘉靖二十年 | S37: 辛丑年十月初八 | T37: M000036W01 | U37: 史氏 | Y37: 进士 | Z37: 南京山东道监察御史; 福建按察佥事; 云南副使 | AA37: 字复之、号克庵、治易经，中宏治己酉年乡试，己未中伦文叙榜进士，任南京山东道监察御史，升福建按察佥事、云南副使，乐恬退引疾乞致仕奉。诏进阶一级，生正统己巳（1449元）八月初五时，殁嘉靖辛丑（1541年）十月初八日，崇祀郡邑乡贤，葬义历鱼形，壬山丙向。配史氏，生己巳（1449年）三月初二日以夫贵，勅封孺人，殁嘉靖甲申（1524年）四月二十日，葬北乡二都宝成寺前大陂龙形乙辰山，辛戌向。子二：日谦、日让。_x000D_ （阳先注：这应当是我们祖上做官做的最大的，明朝中期弘治十二年，中伦文叙榜进士（殿试二甲第 15 名，赐进士出身），也就是说当年的状元是著名的伦文叙，这人是广东人引以为傲的状元，善公是进士。善公做过南京山东道监察御史、福建按察佥事（后任汀漳兵备佥事），进云南按察副使（四品），连他先父也被追封了官，还和刘瑾斗过。_x000D_ 姓名：罗善_x000D_ 字：复之_x000D_ 号：克庵_x000D_ 籍贯：江西吉安府安福县_x000D_ 出身：治《易经》（科举专攻《周易》）_x000D_ 生卒：甲戌年（1454 年）八月初五生，年九十余卒_x000D_ 二、科举履历_x000D_ 弘治二年己酉（1489 年）：中江西乡试（举人）_x000D_ 弘治十二年己未（1499 年）：中伦文叙榜进士（殿试二甲第 15 名，赐进士出身）_x000D_ 三、仕宦经历（与你所述一致）_x000D_ 南京山东道监察御史_x000D_ 任上以刚直、纠劾著称。_x000D_ 升福建按察佥事（后任汀漳兵备佥事）_x000D_ 时宦官刘瑾专权，地方官上任多入都谢恩，罗善独不往_x000D_ 携二僮赴任，裁省供亿、整饬兵备、剿寇有功_x000D_ 改陕西按察佥事_x000D_ 刘瑾葬父于马嵬坡，百官致祭，罗善独不顾而去，瑾恨之未发而败_x000D_ 进云南按察副使（兵备副使）_x000D_ 当道连章举荐，但他淡于名利，引疾乞休_x000D_ 致仕（退休）_x000D_ 归乡后萧然一室、终日凝定_x000D_ 每月朔望，率子孙讲《小学》、考论品行、惩戒不肖_x000D_ 四、历史评价_x000D_ 品行：性孝友、宽和博学，为官清廉刚正、不附权贵_x000D_ 学术：深于《易》，为诸生时以孝弟廉耻教人_x000D_ 结局：高寿九十余，以清德终，为安福罗氏名宦
A38: M000037 | B38: 芄 | C38: 男 | D38: 18 | E38: 中和堂 | F38: M000035 | G38: 正珠 | H38: =INDEX([1]妻子表!$A:$A,MATCH(F38,[1]妻子表!$B:$B,0)) -> M000035W01 | I38: =VLOOKUP(H38,[1]妻子表!$A:$D,4,0) -> 刘氏 | J38: 安福 | K38: 对门岭犬形 | T38: M000037W01 | U38: 旷氏 | AA38: 字景荣，配本里旷氏，同葬对门岭犬形。子一：迅。
A39: M000038 | B39: 日谦 | C39: 男 | D39: 18 | E39: 中和堂 | F39: M000036 | G39: 善 | H39: =INDEX([1]妻子表!$A:$A,MATCH(F39,[1]妻子表!$B:$B,0)) -> M000036W01 | I39: =VLOOKUP(H39,[1]妻子表!$A:$D,4,0) -> 史氏 | J39: 安福 | K39: 大陂龙形 | L39: 68 | M39: 1477.8.11 | N39: 明朝成化十三年 | O39: 丁酉年八月十一 | P39: 鸡 | Q39: 1545.9.6 | R39: 明朝嘉靖二十四年 | S39: 乙巳年九月初六 | T39: M000038W01 | U39: 郭氏 | Y39: 贡生 | Z39: 浙江桐乡县主簿 | AA39: 字士亨、岁贡生，任浙江桐乡县主簿，生成化丁酉（1477年）八月十一日，殁嘉靖乙巳（1545年）九月初六日，葬枫田鲁石江边乌龟潭石榴峰莘夫公墓傍，乙山辛向。配塘东郭氏，生殁葬大陂龙形。子一：应真。
A40: M000039 | B40: 日让 | C40: 男 | D40: 18 | E40: 中和堂 | F40: M000036 | G40: 善 | H40: =INDEX([1]妻子表!$A:$A,MATCH(F40,[1]妻子表!$B:$B,0)) -> M000036W01 | I40: =VLOOKUP(H40,[1]妻子表!$A:$D,4,0) -> 史氏 | J40: 安福 | K40: 本里荷叶盏金龟形 | L40: 79 | M40: 1489.1.1 | N40: 明朝弘治二年 | O40: 己酉年元月初一 | P40: 鸡 | Q40: 1568.1.1 | R40: 明朝隆庆二年 | S40: 戊辰年元月初一 | T40: M000039W01,M000039W02 | U40: 谢氏_x000D_ 李氏 | Y40: 补国学生 | Z40: 福建水师营守备 | AA40: 日让 字以实、号虚白、治易补国学生，任福建水师营守备。生宏治己酉（1489年）五月初九日，殁隆庆戊辰（1568年）十二月初三日，葬枫田石榴峯。配辛里谢氏，续配李氏，殁葬本里荷叶盏金龟形。
...
